20210307 220431.945 INFO             PET0 !!!!!!!!!!!!!!!!!!!!!!!!!!!!!!!!!!!!!!!!!!!!!!!!!!!!!!
20210307 220431.945 INFO             PET0 !!! THE ESMF_LOG IS SET TO OUTPUT ALL LOG MESSAGES !!!
20210307 220431.945 INFO             PET0 !!!     THIS MAY CAUSE SLOWDOWN IN PERFORMANCE     !!!
20210307 220431.945 INFO             PET0 !!! FOR PRODUCTION RUNS, USE:                      !!!
20210307 220431.945 INFO             PET0 !!!                   ESMF_LOGKIND_Multi_On_Error  !!!
20210307 220431.945 INFO             PET0 !!!!!!!!!!!!!!!!!!!!!!!!!!!!!!!!!!!!!!!!!!!!!!!!!!!!!!
20210307 220431.945 INFO             PET0 Running with ESMF Version   : ESMF_8_1_0_beta_snapshot_47-22-gffbbe59
20210307 220431.945 INFO             PET0 ESMF library build date/time: "Mar  7 2021" "21:38:28"
20210307 220431.945 INFO             PET0 ESMF library build location : /glade/scratch/himanshu/relese_8.1.0/python_data/intel_18.0.5_intelmpi_g
20210307 220431.945 INFO             PET0 ESMF_COMM                   : intelmpi
20210307 220431.990 INFO             PET0 ESMF_MOAB                   : enabled
20210307 220431.990 INFO             PET0 ESMF_LAPACK                 : enabled
20210307 220431.990 INFO             PET0 ESMF_NETCDF                 : enabled
20210307 220431.990 INFO             PET0 ESMF_PNETCDF                : disabled
20210307 220431.990 INFO             PET0 ESMF_PIO                    : enabled
20210307 220431.990 INFO             PET0 ESMF_YAMLCPP                : enabled
20210307 220431.990 INFO             PET0 Beginning Test, file ESMC_MeshVTKUTest.C, line 63
20210307 220431.990 INFO             PET0 NUMBER_OF_PROCESSORS 1
20210307 220431.990 INFO             PET0 PASS MeshCreate, ESMC_MeshVTKUTest.C, line 80
20210307 220431.990 ERROR            PET0 ./src/Infrastructure/Mesh/src/ESMCI_MeshCXX.C:1175 ESMCI::MeshVTKHeader() Internal error: Bad condition  - /glade/scratch/himanshu/relese_8.1.0/python_data/intel_18.0.5_intelmpi_g/src/Infrastructure/Mesh/src/Legacy/ESMCI_MeshVTK.C, line:604:Could not open infile:data/testmesh.vtk
20210307 220431.990 ERROR            PET0 ESMC_Mesh.C:475 ESMC_MeshVTKHeader() Internal error: Bad condition  - Internal subroutine call returned Error
20210307 220431.990 INFO             PET0 FAIL MeshVTKHeader, ESMC_MeshVTKUTest.C, line 89, Did not return ESMF_SUCCESS
20210307 220431.990 ERROR            PET0 ./src/Infrastructure/Mesh/src/ESMCI_MeshCXX.C:1175 ESMCI::MeshVTKHeader() Internal error: Bad condition  - /glade/scratch/himanshu/relese_8.1.0/python_data/intel_18.0.5_intelmpi_g/src/Infrastructure/Mesh/src/Legacy/ESMCI_MeshVTK.C, line:604:Could not open infile:data/testmesh.vtk
20210307 220431.990 ERROR            PET0 ESMC_Mesh.C:475 ESMC_MeshVTKHeader() Internal error: Bad condition  - Internal subroutine call returned Error
20210307 220431.990 INFO             PET0 FAIL MeshVTKHeader, ESMC_MeshVTKUTest.C, line 110, Did not return ESMF_SUCCESS
20210307 220431.990 ERROR            PET0 ./src/Infrastructure/Mesh/src/ESMCI_MeshCXX.C:1238 ESMCI::MeshVTKBody() Internal error: Bad condition  - /glade/scratch/himanshu/relese_8.1.0/python_data/intel_18.0.5_intelmpi_g/src/Infrastructure/Mesh/src/Legacy/ESMCI_MeshVTK.C, line:604:Could not open infile:data/testmesh.vtk
20210307 220431.990 ERROR            PET0 ESMC_Mesh.C:498 ESMC_MeshVTKBody() Internal error: Bad condition  - Internal subroutine call returned Error
20210307 220431.990 INFO             PET0 FAIL MeshVTKBody, ESMC_MeshVTKUTest.C, line 129, Did not return ESMF_SUCCESS
20210307 220431.990 ERROR            PET0 ESMC_Mesh.C:352 ESMC_MeshGetLocalNodeCount() Value unrecognized or out of range  - - Mesh must have had its nodes added to get local node count
20210307 220431.990 INFO             PET0 PASS MeshGetLocalNodeCount before MeshAddNodes, ESMC_MeshVTKUTest.C, line 163
20210307 220431.991 INFO             PET0 PASS MeshAddNodes, ESMC_MeshVTKUTest.C, line 172
20210307 220431.991 INFO             PET0 PASS MeshGetLocalNodeCount, ESMC_MeshVTKUTest.C, line 192
20210307 220431.991 ERROR            PET0 ESMC_Mesh.C:417 ESMC_MeshGetLocalElementCount() Value unrecognized or out of range  - - Mesh must have had its elements added to get local element count
20210307 220431.991 INFO             PET0 PASS MeshGetLocalElementCount before MeshAddElements, ESMC_MeshVTKUTest.C, line 206
20210307 220431.991 INFO             PET0 PASS MeshAddElements, ESMC_MeshVTKUTest.C, line 215
20210307 220431.991 INFO             PET0 PASS MeshGetLocalElementCount, ESMC_MeshVTKUTest.C, line 235
20210307 220431.991 INFO             PET0 PASS MeshGetOwnedElementCount, ESMC_MeshVTKUTest.C, line 256
20210307 220431.991 INFO             PET0 PASS MeshGetOwnedNodeCount, ESMC_MeshVTKUTest.C, line 277
20210307 220431.999 ERROR            PET0 ./src/Infrastructure/Mesh/src/ESMCI_MeshCXX.C:1316 ESMCI::MeshVTKBody() Internal error: Bad condition  - Condition {(mef.is_nodal() || mef.is_elemental()) && Numfields() == 1} failed at /glade/scratch/himanshu/relese_8.1.0/python_data/intel_18.0.5_intelmpi_g/src/Infrastructure/Mesh/include/Legacy/ESMCI_MEField.h, line:123
20210307 220431.999 ERROR            PET0 ESMC_Mesh.C:522 ESMC_MeshWrite() Internal error: Bad condition  - Internal subroutine call returned Error
20210307 220431.999 INFO             PET0 FAIL MeshWrite, ESMC_MeshVTKUTest.C, line 297, Did not return ESMF_SUCCESS
20210307 220431.999 INFO             PET0 PASS MeshFreeMemory, ESMC_MeshVTKUTest.C, line 307
20210307 220431.999 INFO             PET0 PASS MeshDestroy, ESMC_MeshVTKUTest.C, line 316
20210307 220431.999 INFO             PET0 Ending Test, file ESMC_MeshVTKUTest.C, line 329
20210307 220431.999 INFO             PET0 Finalizing ESMF
